<?xml version="1.0" ?>

<robot name="ur5" xmlns:xacro="http://www.ros.org/wiki/xacro">

  <xacro:macro name="robotiq_c_model" params="root_link hide_underactuated">
    <joint name="adapter_root_link" type="fixed">
      <parent link="${root_link}" />
      <child link="robotiq_85_adapter_link" />
    </joint>

    <link name="robotiq_85_adapter_link">
      <inertial>
        <mass value="10"/>
        <origin xyz="0 0 0" rpy="0 0 0"/>
        <inertia ixx="1" ixy="0" ixz="0" iyy="1" iyz="0" izz="1"/>
      </inertial>
      <visual>
        <geometry>
          <box size="0.064 0.064 0.012"/>
        </geometry>
        <material name="silver">
          <color rgba="0.7529 0.7529 0.7529 1"/>
        </material>
        <origin rpy="1.5707 0 1.5707" xyz="0 0 0"/>
      </visual>
      <collision>
        <geometry>
          <box size="0.064 0.064 0.012"/>
        </geometry>
        <origin rpy="1.5707 0 1.5707" xyz="0 0 0"/>
      </collision>
    </link>

    <!--  /\  -->
    <joint name="robotiq_85_base_joint" type="fixed">
      <parent link="robotiq_85_adapter_link"/>
      <child link="robotiq_85_base_link"/>
      <axis xyz="1 0 0"/>
      <origin rpy="0 0 0" xyz=".0085 0 -.0041"/>
    </joint>
    <!--  \/  -->

    <link name="robotiq_85_base_link">
      <inertial>
        <mass value="10"/>
        <origin xyz="0 0 0" rpy="0 0 0"/>
        <inertia ixx="1" ixy="0" ixz="0" iyy="1" iyz="0" izz="1"/>
      </inertial>
      <visual>
        <geometry>
          <mesh filename="package://robotiq_c_model_visualization/meshes/robotiq_85_gripper_base.dae"/>
        </geometry>
        <origin rpy="3.1415 0 1.5707" xyz="0 0 0"/>
      </visual>
      <collision>
        <geometry>
          <mesh filename="package://robotiq_c_model_visualization/meshes/robotiq_85_gripper_base.dae"/>
        </geometry>
        <origin rpy="3.1415 0 1.5707" xyz="0 0 0"/>      
      </collision>
    </link>

    <xacro:if value="${hide_underactuated}">
      <!--  /\  -->
      <!--  /\  -->
      <joint name="robotiq_85_left_knuckle_joint" type="revolute">
        <parent link="robotiq_85_base_link"/>
        <child link="robotiq_85_left_knuckle_link"/>
        <axis xyz="1 0 0"/>
        <origin rpy="-1.5707 1.5707 0" xyz=".04191 .0306 0"/>
        <limit lower="0" upper=".8575" velocity="2.0" effort="1000"/>
      </joint>

      <joint name="robotiq_85_right_knuckle_joint" type="revolute">
        <parent link="robotiq_85_base_link"/>
        <child link="robotiq_85_right_knuckle_link"/>
        <axis xyz="1 0 0"/>
        <origin rpy="1.5707 -1.5707 0" xyz=".04191 -.0306 0"/>
        <limit lower="0" upper="1.5707" velocity="2.0" effort="1000"/>
        <xacro:if value="${hide_underactuated}">
          <mimic joint="robotiq_85_left_knuckle_joint" multiplier="1"/>
        </xacro:if>
      </joint>
      <!--  \/  -->
      <!--  \/  -->

      <link name="robotiq_85_left_knuckle_link">
        <inertial>
          <mass value="10"/>
          <origin xyz="0 0 0" rpy="0 0 0"/>
          <inertia ixx="1" ixy="0" ixz="0" iyy="1" iyz="0" izz="1"/>
        </inertial>
        <visual>
          <geometry>
            <mesh filename="package://robotiq_c_model_visualization/meshes/robotiq_85_gripper_joint_0_L.dae"/>
          </geometry>
          <origin rpy="3.14159 -1.5707 0" xyz="0 .04191 -.0306"/>
        </visual>
        <collision>
          <geometry>
            <mesh filename="package://robotiq_c_model_visualization/meshes/robotiq_85_gripper_joint_0_L.dae"/>
          </geometry>
          <origin rpy="3.14159 -1.5707 0" xyz="0 .04191 -.0306"/>
        </collision>
      </link> 

      <link name="robotiq_85_right_knuckle_link">
        <inertial>
          <mass value="10"/>
          <origin xyz="0 0 0" rpy="0 0 0"/>
          <inertia ixx="1" ixy="0" ixz="0" iyy="1" iyz="0" izz="1"/>
        </inertial>
        <visual>
          <geometry>
            <mesh filename="package://robotiq_c_model_visualization/meshes/robotiq_85_gripper_joint_0_R.dae"/>
          </geometry>
          <origin rpy="3.14159 1.5707 0" xyz="0 .04191 -.0306"/>
        </visual>
        <collision>
          <geometry>
            <mesh filename="package://robotiq_c_model_visualization/meshes/robotiq_85_gripper_joint_0_R.dae"/>
          </geometry>
          <origin rpy="3.14159 1.5707 0" xyz="0 .04191 -.0306"/>
        </collision>
      </link>

      <!--  /\  -->
      <!--  /\  -->
      <joint name="robotiq_85_left_finger_joint" type="fixed">
        <parent link="robotiq_85_left_knuckle_link"/>
        <child link="robotiq_85_left_finger_link"/>
        <axis xyz="1 0 0"/>
        <origin rpy="3.1415 0 0" xyz="0 .00508 .03134"/>
        <limit lower="0" upper="1.5707" velocity="2.0" effort="1000"/>
      </joint>

      <joint name="robotiq_85_right_finger_joint" type="fixed">
        <parent link="robotiq_85_right_knuckle_link"/>
        <child link="robotiq_85_right_finger_link"/>
        <axis xyz="1 0 0"/>
        <origin rpy="3.1415 0 0" xyz="0 .00508 .03134"/>
        <limit lower="0" upper="1.5707" velocity="2.0" effort="1000"/>
      </joint>
      <!--  \/  --> 
      <!--  \/  -->  

      <link name="robotiq_85_left_finger_link">
        <inertial>
          <mass value="10"/>
          <origin xyz="0 0 0" rpy="0 0 0"/>
          <inertia ixx="1" ixy="0" ixz="0" iyy="1" iyz="0" izz="1"/>
        </inertial>
        <visual>
          <geometry>
            <mesh filename="package://robotiq_c_model_visualization/meshes/robotiq_85_gripper_joint_1_L.dae"/>
          </geometry>
          <origin rpy="0 1.5707 0" xyz="0 -.03683 .06194"/>
        </visual>
        <collision>
          <geometry>
            <mesh filename="package://robotiq_c_model_visualization/meshes/robotiq_85_gripper_joint_1_L.dae"/>
          </geometry>
          <origin rpy="0 1.5707 0" xyz="0 -.03683 .06194"/>
        </collision>
      </link> 

      <link name="robotiq_85_right_finger_link">
        <inertial>
          <mass value="10"/>
          <origin xyz="0 0 0" rpy="0 0 0"/>
          <inertia ixx="1" ixy="0" ixz="0" iyy="1" iyz="0" izz="1"/>
        </inertial>
        <visual>
          <geometry>
            <mesh filename="package://robotiq_c_model_visualization/meshes/robotiq_85_gripper_joint_1_R.dae"/>
          </geometry>
          <origin rpy="0 -1.5707 0" xyz="0 -.03683 .06194"/>
        </visual>
        <collision>
          <geometry>
            <mesh filename="package://robotiq_c_model_visualization/meshes/robotiq_85_gripper_joint_1_R.dae"/>
          </geometry>
          <origin rpy="0 -1.5707 0" xyz="0 -.03683 .06194"/>
        </collision>
      </link> 
    </xacro:if>

    <!--  /\  -->
    <!--  /\  -->
    <joint name="robotiq_85_left_inner_knuckle_joint" type="revolute">
      <parent link="robotiq_85_base_link"/>
      <child link="robotiq_85_left_inner_knuckle_link"/>
      <axis xyz="1 0 0"/>
      <origin rpy="1.5707 1.5707 0" xyz=".04843 .0127 0"/>
      <limit lower="0" upper="1.5707" velocity="2.0" effort="1000"/>
      <xacro:if value="${hide_underactuated}">
        <mimic joint="robotiq_85_left_knuckle_joint" offset="0"/>
      </xacro:if>
    </joint> 

    <joint name="robotiq_85_right_inner_knuckle_joint" type="revolute">
      <parent link="robotiq_85_base_link"/>
      <child link="robotiq_85_right_inner_knuckle_link"/>
      <axis xyz="1 0 0"/>
      <origin rpy="-1.5707 -1.5707 0" xyz=".04843 -.0127 0"/>
      <limit lower="0" upper="1.5707" velocity="2.0" effort="1000"/>
      <xacro:if value="${hide_underactuated}">
        <mimic joint="robotiq_85_left_knuckle_joint" offset="0"/>
      </xacro:if>
    </joint>
    <!--  \/  --> 
    <!--  \/  -->  

    <link name="robotiq_85_left_inner_knuckle_link">
      <inertial>
        <mass value="10"/>
        <origin xyz="0 0 0" rpy="0 0 0"/>
        <inertia ixx="1" ixy="0" ixz="0" iyy="1" iyz="0" izz="1"/>
      </inertial>
      <visual>
        <geometry>
          <mesh filename="package://robotiq_c_model_visualization/meshes/robotiq_85_gripper_joint_2_L.dae"/>
        </geometry>
        <origin rpy="0 1.5707 0" xyz="0 -.04843 .0127"/>
      </visual>
      <collision>
        <geometry>
          <mesh filename="package://robotiq_c_model_visualization/meshes/robotiq_85_gripper_joint_2_L.dae"/>
        </geometry>
        <origin rpy="0 1.5707 0" xyz="0 -.04843 .0127"/>
      </collision>
    </link>

    <link name="robotiq_85_right_inner_knuckle_link">
      <inertial>
        <mass value="10"/>
        <origin xyz="0 0 0" rpy="0 0 0"/>
        <inertia ixx="1" ixy="0" ixz="0" iyy="1" iyz="0" izz="1"/>
      </inertial>
      <visual>
        <geometry>
          <mesh filename="package://robotiq_c_model_visualization/meshes/robotiq_85_gripper_joint_2_R.dae"/>
        </geometry>
        <origin rpy="0 -1.5707 0" xyz="0 -.04843 .0127"/>
      </visual>
      <collision>
        <geometry>
          <mesh filename="package://robotiq_c_model_visualization/meshes/robotiq_85_gripper_joint_2_R.dae"/>
        </geometry>
        <origin rpy="0 -1.5707 0" xyz="0 -.04843 .0127"/>
      </collision>
    </link>

    <!--  /\  -->
    <!--  /\  -->
    <joint name="robotiq_85_left_finger_tip_joint" type="revolute">
      <parent link="robotiq_85_left_inner_knuckle_link"/>
      <child link="robotiq_85_left_finger_tip_link"/>
      <axis xyz="1 0 0"/>
      <origin rpy="0 0 0" xyz="0 .04196 -.0388"/>
      <limit lower="0" upper="1.5707" velocity="2.0" effort="1000"/>
      <xacro:if value="${hide_underactuated}">
        <mimic joint="robotiq_85_left_knuckle_joint" multiplier="-1"/>
      </xacro:if>
    </joint>

    <joint name="robotiq_85_right_finger_tip_joint" type="revolute">
      <parent link="robotiq_85_right_inner_knuckle_link"/>
      <child link="robotiq_85_right_finger_tip_link"/>
      <axis xyz="1 0 0"/>
      <origin rpy="0 0 0" xyz="0 .04196 -.0388"/>
      <limit lower="0" upper="1.5707" velocity="2.0" effort="1000"/>
      <xacro:if value="${hide_underactuated}">
        <mimic joint="robotiq_85_left_knuckle_joint" multiplier="-1"/>
      </xacro:if>
    </joint>
    <!--  \/  --> 
    <!--  \/  -->  

    <link name="robotiq_85_left_finger_tip_link">
      <inertial>
        <mass value="10"/>
        <origin xyz="0 0 0" rpy="0 0 0"/>
        <inertia ixx="1" ixy="0" ixz="0" iyy="1" iyz="0" izz="1"/>
      </inertial>
      <visual>
        <geometry>
          <mesh filename="package://robotiq_c_model_visualization/meshes/robotiq_85_gripper_joint_3_L.dae"/>
        </geometry>
        <origin rpy="0 1.5707 0" xyz="0 -.090381 .051505"/>
      </visual>
      <collision>
        <geometry>
          <mesh filename="package://robotiq_c_model_visualization/meshes/robotiq_85_gripper_joint_3_L.dae"/>
        </geometry>
        <origin rpy="0 1.5707 0" xyz="0 -.090381 .051505"/>
      </collision>
    </link> 

    <link name="robotiq_85_right_finger_tip_link">
      <inertial>
        <mass value="10"/>
        <origin xyz="0 0 0" rpy="0 0 0"/>
        <inertia ixx="1" ixy="0" ixz="0" iyy="1" iyz="0" izz="1"/>
      </inertial>
      <visual>
        <geometry>
          <mesh filename="package://robotiq_c_model_visualization/meshes/robotiq_85_gripper_joint_3_R.dae"/>
        </geometry>
        <origin rpy="0 -1.5707 0" xyz="0 -.090381 .051505"/>
      </visual>
      <collision>
        <geometry>
          <mesh filename="package://robotiq_c_model_visualization/meshes/robotiq_85_gripper_joint_3_R.dae"/>
        </geometry>
        <origin rpy="0 -1.5707 0" xyz="0 -.090381 .051505"/>
      </collision>
    </link>

    <xacro:if value="${hide_underactuated}">
      <transmission name="robotiq_85_left_knuckle_trans">
        <type>transmission_interface/SimpleTransmission</type>
        <joint name="robotiq_85_left_knuckle_joint"/>
        <actuator name="robotiq_85_left_knuckle_motor">
          <hardwareInterface>PositionJointInterface</hardwareInterface>
          <mechanicalReduction>1</mechanicalReduction>
        </actuator>
      </transmission>

      <transmission name="robotiq_85_right_knuckle_trans">
        <type>transmission_interface/SimpleTransmission</type>
        <joint name="robotiq_85_right_knuckle_joint"/>
        <actuator name="robotiq_85_right_knuckle_motor">
          <hardwareInterface>PositionJointInterface</hardwareInterface>
          <mechanicalReduction>1</mechanicalReduction>
        </actuator>
      </transmission>
    </xacro:if>

    <transmission name="robotiq_85_left_inner_knuckle_trans">
      <type>transmission_interface/SimpleTransmission</type>
      <joint name="robotiq_85_left_inner_knuckle_joint"/>
      <actuator name="robotiq_85_left_inner_knuckle_motor">
        <hardwareInterface>PositionJointInterface</hardwareInterface>
        <mechanicalReduction>1</mechanicalReduction>
      </actuator>
    </transmission>

    <transmission name="robotiq_85_right_inner_knuckle_trans">
      <type>transmission_interface/SimpleTransmission</type>
      <joint name="robotiq_85_right_inner_knuckle_joint"/>
      <actuator name="robotiq_85_right_inner_knuckle_motor">
        <hardwareInterface>PositionJointInterface</hardwareInterface>
        <mechanicalReduction>1</mechanicalReduction>
      </actuator>
    </transmission>

    <transmission name="robotiq_85_left_finger_tip_trans">
      <type>transmission_interface/SimpleTransmission</type>
      <joint name="robotiq_85_left_finger_tip_joint"/>
      <actuator name="robotiq_85_left_finger_tip_motor">
        <hardwareInterface>PositionJointInterface</hardwareInterface>
        <mechanicalReduction>1</mechanicalReduction>
      </actuator>
    </transmission>

    <transmission name="robotiq_85_right_finger_tip_trans">
      <type>transmission_interface/SimpleTransmission</type>
      <joint name="robotiq_85_right_finger_tip_joint"/>
      <actuator name="robotiq_85_right_finger_tip_motor">
        <hardwareInterface>PositionJointInterface</hardwareInterface>
        <mechanicalReduction>1</mechanicalReduction>
      </actuator>
    </transmission>

    <gazebo reference="robotiq_85_adapter_link">
      <selfCollide>true</selfCollide>
      <gravity>true</gravity>
      <turnGravityOff>true</turnGravityOff>
    </gazebo>
    <gazebo reference="robotiq_85_base_link">
      <selfCollide>true</selfCollide>
      <gravity>true</gravity>
      <turnGravityOff>true</turnGravityOff>
    </gazebo>
    <xacro:if value="${hide_underactuated}">
      <gazebo reference="robotiq_85_left_knuckle_link">
        <selfCollide>true</selfCollide>
        <gravity>true</gravity>
        <turnGravityOff>true</turnGravityOff>
      </gazebo>
      <gazebo reference="robotiq_85_right_knuckle_link">
        <selfCollide>true</selfCollide>
        <gravity>true</gravity>
        <turnGravityOff>true</turnGravityOff>
      </gazebo>
      <gazebo reference="robotiq_85_left_finger_link">
        <selfCollide>true</selfCollide>
        <gravity>true</gravity>
        <turnGravityOff>true</turnGravityOff>
      </gazebo>
      <gazebo reference="robotiq_85_right_finger_link">
        <selfCollide>true</selfCollide>
        <gravity>true</gravity>
        <turnGravityOff>true</turnGravityOff>
      </gazebo>
    </xacro:if>
    <gazebo reference="robotiq_85_left_inner_knuckle_link">
      <selfCollide>true</selfCollide>
      <gravity>true</gravity>
      <turnGravityOff>true</turnGravityOff>
    </gazebo>
    <gazebo reference="robotiq_85_right_inner_knuckle_link">
      <selfCollide>true</selfCollide>
      <gravity>true</gravity>
      <turnGravityOff>true</turnGravityOff>
    </gazebo>
  </xacro:macro>
  <gazebo reference="robotiq_85_left_finger_tip_link">
    <selfCollide>true</selfCollide>
    <gravity>true</gravity>
    <turnGravityOff>true</turnGravityOff>
  </gazebo>
  <gazebo reference="robotiq_85_right_finger_tip_link">
    <selfCollide>true</selfCollide>
    <gravity>true</gravity>
    <turnGravityOff>true</turnGravityOff>
  </gazebo>

</robot>
