<?xml version="1.0" ?>
<!-- =================================================================================== -->
<!-- |    This document was autogenerated by xacro from ur5_joint_limited_robot.urdf.xacro | -->
<!-- |    EDITING THIS FILE BY HAND IS NOT RECOMMENDED                                 | -->
<!-- =================================================================================== -->
<robot name="ur5" xmlns:xacro="http://www.ros.org/wiki/xacro">
  <!-- common stuff -->
  <gazebo>
    <plugin filename="libgazebo_ros_power_monitor.so" name="gazebo_ros_power_monitor_controller">
      <alwaysOn>true</alwaysOn>
      <updateRate>1.0</updateRate>
      <timeout>5</timeout>
      <powerStateTopic>power_state</powerStateTopic>
      <powerStateRate>10.0</powerStateRate>
      <fullChargeCapacity>87.78</fullChargeCapacity>
      <dischargeRate>-474</dischargeRate>
      <chargeRate>525</chargeRate>
      <dischargeVoltage>15.52</dischargeVoltage>
      <chargeVoltage>16.41</chargeVoltage>
      <selfCollide>true</selfCollide>
      <turnGravityOff>false</turnGravityOff>
      <gravity>true</gravity>
    </plugin>
  </gazebo>
  <!-- ur5 -->
  <material name="UR/Blue">
    <color rgba="0.0 0.0 0.8 1.0"/>
  </material>
  <material name="UR/Grey">
    <color rgba="0.7 0.7 0.7 1.0"/>
  </material>
  <link name="world" />
  <joint name= "world_joint" type="fixed">
    <parent link="world"/>
    <child link="base_link"/>
    <origin rpy="0.0 0.0 0.0" xyz="0.0 0.0 0.0"/>
  </joint>
  <!-- arm -->
  <link name="base_link">
    <visual>
      <geometry>
        <mesh filename="package://ur_description/meshes/ur5/visual/Base.dae"/>
      </geometry>
      <origin rpy="0.0 0.0 2.3561944875" xyz="0.0 0.0 0.003"/>
    </visual>
    <collision>
      <geometry>
        <mesh filename="package://ur_description/meshes/ur5/collision/Base.dae"/>
      </geometry>
      <!-- <origin rpy="0.0 0.0 0.0" xyz="0.0 0.0 -0.009159"/> -->
    </collision>
    <inertial>
      <mass value="4.0"/>
      <inertia ixx="1.0" ixy="0.0" ixz="0.0" iyy="1.0" iyz="0.0" izz="1.0"/>
    </inertial>
  </link>
  <joint name="shoulder_pan_joint" type="revolute">
    <parent link="base_link"/>
    <child link="shoulder_link"/>
    <origin rpy="0.0 0.0 0.0" xyz="0.0 0.0 0.089159"/>
    <axis xyz="0 0 1"/>
    <limit effort="150.0" lower="-3.14159265" upper="3.14159265" velocity="3.14159265"/>
    <dynamics damping="0.4" friction="0.0"/>
  </joint>
  <link name="shoulder_link">
    <visual>
      <geometry>
        <mesh filename="package://ur_description/meshes/ur5/visual/Shoulder.dae"/>
      </geometry>
    </visual>
    <collision>
      <geometry>
        <mesh filename="package://ur_description/meshes/ur5/collision/Shoulder.dae"/>
      </geometry>
      <!-- <origin rpy="0.0 0.0 0.0" xyz="0.0 0.0 -0.009159"/> -->
    </collision>
    <inertial>
      <mass value="3.7"/>
      <inertia ixx="1.0" ixy="0.0" ixz="0.0" iyy="1.0" iyz="0.0" izz="1.0"/>
      <origin rpy="0.0 0.0 0.0" xyz="0.0 0.00193 -0.02561"/>
    </inertial>
  </link>
  <joint name="shoulder_lift_joint" type="revolute">
    <parent link="shoulder_link"/>
    <child link="upper_arm_link"/>
    <origin rpy="0.0 1.570796325 0.0" xyz="0.0 0.13585 0.0"/>
    <axis xyz="0 1 0"/>
    <limit effort="150.0" lower="-3.14159265" upper="3.14159265" velocity="3.14159265"/>
    <dynamics damping="0.4" friction="0.0"/>
  </joint>
  <link name="upper_arm_link">
    <visual>
      <geometry>
        <mesh filename="package://ur_description/meshes/ur5/visual/UpperArm.dae"/>
      </geometry>
      <origin rpy="0.0 0.0 0.0" xyz="0.0 0.0 0.0"/>
    </visual>
    <collision>
      <geometry>
        <mesh filename="package://ur_description/meshes/ur5/collision/UpperArm.dae"/>
      </geometry>
      <!--       <origin rpy="0.0 0.0 0.0" xyz="0.0 0.0 0.2125"/> -->
    </collision>
    <inertial>
      <mass value="8.393"/>
      <inertia ixx="1.0" ixy="0.0" ixz="0.0" iyy="1.0" iyz="0.0" izz="1.0"/>
      <origin rpy="0.0 0.0 0.0" xyz="0.0 -0.024201 0.2125"/>
    </inertial>
  </link>
  <joint name="elbow_joint" type="revolute">
    <parent link="upper_arm_link"/>
    <child link="forearm_link"/>
    <origin rpy="0.0 0.0 0.0" xyz="0.0 -0.1197 0.425"/>
    <axis xyz="0 1 0"/>
    <limit effort="150.0" lower="-3.14159265" upper="3.14159265" velocity="3.14159265"/>
    <dynamics damping="0.4" friction="0.0"/>
  </joint>
  <link name="forearm_link">
    <visual>
      <geometry>
        <mesh filename="package://ur_description/meshes/ur5/visual/Forearm.dae"/>
      </geometry>
    </visual>
    <collision>
      <geometry>
        <mesh filename="package://ur_description/meshes/ur5/collision/Forearm.dae"/>
      </geometry>
      <!--       <origin rpy="0.0 0.0 0.0" xyz="0.0 0.0 0.196125"/> -->
    </collision>
    <inertial>
      <mass value="2.275"/>
      <origin rpy="0.0 0.0 0.0" xyz="0.0 0.0265 0.11993"/>
      <inertia ixx="1.0" ixy="0.0" ixz="0.0" iyy="1.0" iyz="0.0" izz="1.0"/>
    </inertial>
  </link>
  <joint name="wrist_1_joint" type="revolute">
    <parent link="forearm_link"/>
    <child link="wrist_1_link"/>
    <origin rpy="0.0 1.570796325 0.0" xyz="0.0 0.0 0.39225"/>
    <axis xyz="0 1 0"/>
    <limit effort="28.0" lower="-3.14159265" upper="0.7853981625" velocity="3.14159265"/>
    <dynamics damping="0.3" friction="0.0"/>
  </joint>
  <link name="wrist_1_link">
    <visual>
      <geometry>
        <mesh filename="package://ur_description/meshes/ur5/visual/Wrist1.dae"/>
      </geometry>
      <origin rpy="0.0 1.570796325 0.0" xyz="0.0 0.093 0.0"/>
    </visual>
    <collision>
      <geometry>
        <mesh filename="package://ur_description/meshes/ur5/collision/Wrist1.dae"/>
      </geometry>
      <origin rpy="0.0 1.570796325 0.0" xyz="0.0 0.093 0.0"/>
    </collision>
    <inertial>
      <mass value="1.219"/>
      <origin rpy="0.0 0.0 0.0" xyz="0.0 0.110949 0.01634"/>
      <inertia ixx="1.0" ixy="0.0" ixz="0.0" iyy="1.0" iyz="0.0" izz="1.0"/>
    </inertial>
  </link>
  <joint name="wrist_2_joint" type="revolute">
    <parent link="wrist_1_link"/>
    <child link="wrist_2_link"/>
    <origin rpy="0.0 0.0 0.0" xyz="0.0 0.093 0.0"/>
    <axis xyz="0 0 1"/>
    <limit effort="28.0" lower="-3.14159265" upper="3.14159265" velocity="3.14159265"/>
    <dynamics damping="0.3" friction="0.0"/>
  </joint>
  <link name="wrist_2_link">
    <visual>
      <geometry>
        <mesh filename="package://ur_description/meshes/ur5/visual/Wrist2.dae"/>
      </geometry>
      <origin rpy="0.0 0.0 0.0" xyz="0.0 0.0 0.09465"/>
    </visual>
    <collision>
      <geometry>
        <mesh filename="package://ur_description/meshes/ur5/collision/Wrist2.dae"/>
      </geometry>
      <origin rpy="0.0 0.0 0.0" xyz="0.0 0.0 0.09465"/>
    </collision>
    <inertial>
      <mass value="1.219"/>
      <origin rpy="0.0 0.0 0.0" xyz="0.0 0.0018 0.11099"/>
      <inertia ixx="1.0" ixy="0.0" ixz="0.0" iyy="1.0" iyz="0.0" izz="1.0"/>
    </inertial>
  </link>
  <joint name="wrist_3_joint" type="revolute">
    <parent link="wrist_2_link"/>
    <child link="wrist_3_link"/>
    <origin rpy="0.0 0.0 0.0" xyz="0.0 0.0 0.09465"/>
    <axis xyz="0 1 0"/>
    <limit effort="28.0" lower="-3.14159265" upper="3.14159265" velocity="3.14159265"/>
    <dynamics damping="0.3" friction="0.0"/>
  </joint>
  <link name="wrist_3_link">
    <visual>
      <geometry>
        <mesh filename="package://ur_description/meshes/ur5/visual/Wrist3.dae"/>
      </geometry>
    </visual>
    <collision>
      <geometry>
        <mesh filename="package://ur_description/meshes/ur5/collision/Wrist3.dae"/>
      </geometry>
    </collision>
    <inertial>
      <mass value="0.1879"/>
      <origin rpy="0.0 0.0 0.0" xyz="0.0 0.001159 0.0"/>
      <inertia ixx="1.0" ixy="0.0" ixz="0.0" iyy="1.0" iyz="0.0" izz="1.0"/>
    </inertial>
  </link>
  <joint name="ee_fixed_joint" type="fixed">
    <parent link="wrist_3_link"/>
    <child link="robotiq_85_adapter_link"/>
    <origin rpy="0.0 0.0 1.570796325" xyz="0.0 0.0823 0.0"/>
  </joint>
  <!-- <link name="ee_link"/> -->







  <link name="robotiq_85_adapter_link">
<!--     <inertial>
      <mass value="10"/>
      <origin xyz="0 0 0" rpy="0 0 0"/>
      <inertia ixx="1" ixy="0" ixz="0" iyy="1" iyz="0" izz="1"/>
    </inertial>
    <visual>
      <geometry>
        <mesh filename="package://robotiq_c_model_visualization/meshes/robotiq_85_gripper_adapter_plate.dae"/>
      </geometry>
      <origin rpy="1.5707 0 1.5707" xyz="0 0 0"/>
    </visual> -->
    <inertial>
      <mass value="10"/>
      <origin xyz="0 0 0" rpy="0 0 0"/>
      <inertia ixx="1" ixy="0" ixz="0" iyy="1" iyz="0" izz="1"/>
    </inertial>
    <visual>
      <geometry>
        <box size="0.064 0.064 0.012"/>
      </geometry>
      <material name="silver">
        <color rgba="0.7529 0.7529 0.7529 1"/>
      </material>
      <origin rpy="1.5707 0 1.5707" xyz="0 0 0"/>
    </visual>
    <collision>
      <geometry>
        <box size="0.064 0.064 0.012"/>
      </geometry>
      <origin rpy="1.5707 0 1.5707" xyz="0 0 0"/>
    </collision>
  </link>

  <!--  /\  -->
  <joint name="robotiq_85_base_joint" type="fixed">
    <parent link="robotiq_85_adapter_link"/>
    <child link="robotiq_85_base_link"/>
    <axis xyz="1 0 0"/>
    <origin rpy="0 0 0" xyz=".0085 0 -.0041"/>
  </joint>
  <!--  \/  -->

  <link name="robotiq_85_base_link">
    <inertial>
      <mass value="10"/>
      <origin xyz="0 0 0" rpy="0 0 0"/>
      <inertia ixx="1" ixy="0" ixz="0" iyy="1" iyz="0" izz="1"/>
    </inertial>
    <visual>
      <geometry>
        <mesh filename="package://robotiq_c_model_visualization/meshes/robotiq_85_gripper_base.dae"/>
      </geometry>
      <origin rpy="3.1415 0 1.5707" xyz="0 0 0"/>
    </visual>
    <collision>
      <geometry>
        <mesh filename="package://robotiq_c_model_visualization/meshes/robotiq_85_gripper_base.dae"/>
      </geometry>
      <origin rpy="3.1415 0 1.5707" xyz="0 0 0"/>      
    </collision>
  </link>

  <!--  /\  -->
  <!--  /\  -->
  <joint name="robotiq_85_left_knuckle_joint" type="revolute">
    <parent link="robotiq_85_base_link"/>
    <child link="robotiq_85_left_knuckle_link"/>
    <axis xyz="1 0 0"/>
    <origin rpy="-1.5707 1.5707 0" xyz=".04191 .0306 0"/>
    <limit lower="0" upper=".8575" velocity="2.0" effort="1000"/>
  </joint>

  <joint name="robotiq_85_right_knuckle_joint" type="revolute">
    <parent link="robotiq_85_base_link"/>
    <child link="robotiq_85_right_knuckle_link"/>
    <axis xyz="1 0 0"/>
    <origin rpy="1.5707 -1.5707 0" xyz=".04191 -.0306 0"/>
    <limit lower="0" upper="1.5707" velocity="2.0" effort="1000"/>
    <mimic joint="robotiq_85_left_knuckle_joint" multiplier="1"/>
  </joint>
  <!--  \/  -->
  <!--  \/  -->

  <link name="robotiq_85_left_knuckle_link">
    <inertial>
      <mass value="10"/>
      <origin xyz="0 0 0" rpy="0 0 0"/>
      <inertia ixx="1" ixy="0" ixz="0" iyy="1" iyz="0" izz="1"/>
    </inertial>
    <visual>
      <geometry>
        <mesh filename="package://robotiq_c_model_visualization/meshes/robotiq_85_gripper_joint_0_L.dae"/>
      </geometry>
      <origin rpy="3.14159 -1.5707 0" xyz="0 .04191 -.0306"/>
    </visual>
    <collision>
      <geometry>
        <mesh filename="package://robotiq_c_model_visualization/meshes/robotiq_85_gripper_joint_0_L.dae"/>
      </geometry>
      <origin rpy="3.14159 -1.5707 0" xyz="0 .04191 -.0306"/>
    </collision>
  </link> 

  <link name="robotiq_85_right_knuckle_link">
    <inertial>
      <mass value="10"/>
      <origin xyz="0 0 0" rpy="0 0 0"/>
      <inertia ixx="1" ixy="0" ixz="0" iyy="1" iyz="0" izz="1"/>
    </inertial>
    <visual>
      <geometry>
        <mesh filename="package://robotiq_c_model_visualization/meshes/robotiq_85_gripper_joint_0_R.dae"/>
      </geometry>
      <origin rpy="3.14159 1.5707 0" xyz="0 .04191 -.0306"/>
    </visual>
    <collision>
      <geometry>
        <mesh filename="package://robotiq_c_model_visualization/meshes/robotiq_85_gripper_joint_0_R.dae"/>
      </geometry>
      <origin rpy="3.14159 1.5707 0" xyz="0 .04191 -.0306"/>
    </collision>
  </link>

  <!--  /\  -->
  <!--  /\  -->
  <joint name="robotiq_85_left_finger_joint" type="fixed">
    <parent link="robotiq_85_left_knuckle_link"/>
    <child link="robotiq_85_left_finger_link"/>
    <axis xyz="1 0 0"/>
    <origin rpy="3.1415 0 0" xyz="0 .00508 .03134"/>
    <limit lower="0" upper="1.5707" velocity="2.0" effort="1000"/>
  </joint>

  <joint name="robotiq_85_right_finger_joint" type="fixed">
    <parent link="robotiq_85_right_knuckle_link"/>
    <child link="robotiq_85_right_finger_link"/>
    <axis xyz="1 0 0"/>
    <origin rpy="3.1415 0 0" xyz="0 .00508 .03134"/>
    <limit lower="0" upper="1.5707" velocity="2.0" effort="1000"/>
  </joint>
  <!--  \/  --> 
  <!--  \/  -->  

  <link name="robotiq_85_left_finger_link">
    <inertial>
      <mass value="10"/>
      <origin xyz="0 0 0" rpy="0 0 0"/>
      <inertia ixx="1" ixy="0" ixz="0" iyy="1" iyz="0" izz="1"/>
    </inertial>
    <visual>
      <geometry>
        <mesh filename="package://robotiq_c_model_visualization/meshes/robotiq_85_gripper_joint_1_L.dae"/>
      </geometry>
      <origin rpy="0 1.5707 0" xyz="0 -.03683 .06194"/>
    </visual>
    <collision>
      <geometry>
        <mesh filename="package://robotiq_c_model_visualization/meshes/robotiq_85_gripper_joint_1_L.dae"/>
      </geometry>
      <origin rpy="0 1.5707 0" xyz="0 -.03683 .06194"/>
    </collision>
  </link> 

  <link name="robotiq_85_right_finger_link">
    <inertial>
      <mass value="10"/>
      <origin xyz="0 0 0" rpy="0 0 0"/>
      <inertia ixx="1" ixy="0" ixz="0" iyy="1" iyz="0" izz="1"/>
    </inertial>
    <visual>
      <geometry>
        <mesh filename="package://robotiq_c_model_visualization/meshes/robotiq_85_gripper_joint_1_R.dae"/>
      </geometry>
      <origin rpy="0 -1.5707 0" xyz="0 -.03683 .06194"/>
    </visual>
    <collision>
      <geometry>
        <mesh filename="package://robotiq_c_model_visualization/meshes/robotiq_85_gripper_joint_1_R.dae"/>
      </geometry>
      <origin rpy="0 -1.5707 0" xyz="0 -.03683 .06194"/>
    </collision>
  </link> 

  <!--  /\  -->
  <!--  /\  -->
  <joint name="robotiq_85_left_inner_knuckle_joint" type="revolute">
    <parent link="robotiq_85_base_link"/>
    <child link="robotiq_85_left_inner_knuckle_link"/>
    <axis xyz="1 0 0"/>
    <origin rpy="1.5707 1.5707 0" xyz=".04843 .0127 0"/>
    <limit lower="0" upper="1.5707" velocity="2.0" effort="1000"/>
    <mimic joint="robotiq_85_left_knuckle_joint" offset="0"/>
  </joint> 

  <joint name="robotiq_85_right_inner_knuckle_joint" type="revolute">
    <parent link="robotiq_85_base_link"/>
    <child link="robotiq_85_right_inner_knuckle_link"/>
    <axis xyz="1 0 0"/>
    <origin rpy="-1.5707 -1.5707 0" xyz=".04843 -.0127 0"/>
    <limit lower="0" upper="1.5707" velocity="2.0" effort="1000"/>
    <mimic joint="robotiq_85_left_knuckle_joint" offset="0"/>
  </joint>
  <!--  \/  --> 
  <!--  \/  -->  

  <link name="robotiq_85_left_inner_knuckle_link">
    <inertial>
      <mass value="10"/>
      <origin xyz="0 0 0" rpy="0 0 0"/>
      <inertia ixx="1" ixy="0" ixz="0" iyy="1" iyz="0" izz="1"/>
    </inertial>
    <visual>
      <geometry>
        <mesh filename="package://robotiq_c_model_visualization/meshes/robotiq_85_gripper_joint_2_L.dae"/>
      </geometry>
      <origin rpy="0 1.5707 0" xyz="0 -.04843 .0127"/>
    </visual>
    <collision>
      <geometry>
        <mesh filename="package://robotiq_c_model_visualization/meshes/robotiq_85_gripper_joint_2_L.dae"/>
      </geometry>
      <origin rpy="0 1.5707 0" xyz="0 -.04843 .0127"/>
    </collision>
  </link>

  <link name="robotiq_85_right_inner_knuckle_link">
    <inertial>
      <mass value="10"/>
      <origin xyz="0 0 0" rpy="0 0 0"/>
      <inertia ixx="1" ixy="0" ixz="0" iyy="1" iyz="0" izz="1"/>
    </inertial>
    <visual>
      <geometry>
        <mesh filename="package://robotiq_c_model_visualization/meshes/robotiq_85_gripper_joint_2_R.dae"/>
      </geometry>
      <origin rpy="0 -1.5707 0" xyz="0 -.04843 .0127"/>
    </visual>
    <collision>
      <geometry>
        <mesh filename="package://robotiq_c_model_visualization/meshes/robotiq_85_gripper_joint_2_R.dae"/>
      </geometry>
      <origin rpy="0 -1.5707 0" xyz="0 -.04843 .0127"/>
    </collision>
  </link>

  <!--  /\  -->
  <!--  /\  -->
  <joint name="robotiq_85_left_finger_tip_joint" type="revolute">
    <parent link="robotiq_85_left_inner_knuckle_link"/>
    <child link="robotiq_85_left_finger_tip_link"/>
    <axis xyz="1 0 0"/>
    <origin rpy="0 0 0" xyz="0 .04196 -.0388"/>
    <limit lower="0" upper="1.5707" velocity="2.0" effort="1000"/>
    <mimic joint="robotiq_85_left_knuckle_joint" multiplier="-1"/>
  </joint>

  <joint name="robotiq_85_right_finger_tip_joint" type="revolute">
    <parent link="robotiq_85_right_inner_knuckle_link"/>
    <child link="robotiq_85_right_finger_tip_link"/>
    <axis xyz="1 0 0"/>
    <origin rpy="0 0 0" xyz="0 .04196 -.0388"/>
    <limit lower="0" upper="1.5707" velocity="2.0" effort="1000"/>
    <mimic joint="robotiq_85_left_knuckle_joint" multiplier="-1"/>
  </joint>
  <!--  \/  --> 
  <!--  \/  -->  

  <link name="robotiq_85_left_finger_tip_link">
    <inertial>
      <mass value="10"/>
      <origin xyz="0 0 0" rpy="0 0 0"/>
      <inertia ixx="1" ixy="0" ixz="0" iyy="1" iyz="0" izz="1"/>
    </inertial>
    <visual>
      <geometry>
        <mesh filename="package://robotiq_c_model_visualization/meshes/robotiq_85_gripper_joint_3_L.dae"/>
      </geometry>
      <origin rpy="0 1.5707 0" xyz="0 -.090381 .051505"/>
    </visual>
    <collision>
      <geometry>
        <mesh filename="package://robotiq_c_model_visualization/meshes/robotiq_85_gripper_joint_3_L.dae"/>
      </geometry>
      <origin rpy="0 1.5707 0" xyz="0 -.090381 .051505"/>
    </collision>
  </link> 

  <link name="robotiq_85_right_finger_tip_link">
    <inertial>
      <mass value="10"/>
      <origin xyz="0 0 0" rpy="0 0 0"/>
      <inertia ixx="1" ixy="0" ixz="0" iyy="1" iyz="0" izz="1"/>
    </inertial>
    <visual>
      <geometry>
        <mesh filename="package://robotiq_c_model_visualization/meshes/robotiq_85_gripper_joint_3_R.dae"/>
      </geometry>
      <origin rpy="0 -1.5707 0" xyz="0 -.090381 .051505"/>
    </visual>
    <collision>
      <geometry>
        <mesh filename="package://robotiq_c_model_visualization/meshes/robotiq_85_gripper_joint_3_R.dae"/>
      </geometry>
      <origin rpy="0 -1.5707 0" xyz="0 -.090381 .051505"/>
    </collision>
  </link>





  <transmission name="shoulder_pan_trans">
    <type>transmission_interface/SimpleTransmission</type>
    <joint name="shoulder_pan_joint"/>
    <actuator name="shoulder_pan_motor">
      <hardwareInterface>EffortJointInterface</hardwareInterface>
      <mechanicalReduction>1</mechanicalReduction>
    </actuator>
  </transmission>
  <transmission name="shoulder_lift_trans">
    <type>transmission_interface/SimpleTransmission</type>
    <joint name="shoulder_lift_joint"/>
    <actuator name="shoulder_lift_motor">
      <hardwareInterface>EffortJointInterface</hardwareInterface>
      <mechanicalReduction>1</mechanicalReduction>
    </actuator>
  </transmission>
  <transmission name="elbow_trans">
    <type>transmission_interface/SimpleTransmission</type>
    <joint name="elbow_joint"/>
    <actuator name="elbow_motor">
      <hardwareInterface>EffortJointInterface</hardwareInterface>
      <mechanicalReduction>1</mechanicalReduction>
    </actuator>
  </transmission>
  <transmission name="wrist_1_trans">
    <type>transmission_interface/SimpleTransmission</type>
    <joint name="wrist_1_joint"/>
    <actuator name="wrist_1_motor">
      <hardwareInterface>EffortJointInterface</hardwareInterface>
      <mechanicalReduction>1</mechanicalReduction>
    </actuator>
  </transmission>
  <transmission name="wrist_2_trans">
    <type>transmission_interface/SimpleTransmission</type>
    <joint name="wrist_2_joint"/>
    <actuator name="wrist_2_motor">
      <hardwareInterface>EffortJointInterface</hardwareInterface>
      <mechanicalReduction>1</mechanicalReduction>
    </actuator>
  </transmission>
  <transmission name="wrist_3_trans">
    <type>transmission_interface/SimpleTransmission</type>
    <joint name="wrist_3_joint"/>
    <actuator name="wrist_3_motor">
      <hardwareInterface>EffortJointInterface</hardwareInterface>
      <mechanicalReduction>1</mechanicalReduction>
    </actuator>
  </transmission>

  <!-- <transmission name="robotiq_85_left_knuckle_trans">
    <type>transmission_interface/SimpleTransmission</type>
    <joint name="robotiq_85_left_knuckle_joint"/>
    <actuator name="robotiq_85_left_knuckle_motor">
      <hardwareInterface>EffortJointInterface</hardwareInterface>
      <mechanicalReduction>1</mechanicalReduction>
    </actuator>
  </transmission>

  <transmission name="robotiq_85_right_knuckle_trans">
    <type>transmission_interface/SimpleTransmission</type>
    <joint name="robotiq_85_right_knuckle_joint"/>
    <actuator name="robotiq_85_right_knuckle_motor">
      <hardwareInterface>EffortJointInterface</hardwareInterface>
      <mechanicalReduction>1</mechanicalReduction>
    </actuator>
  </transmission>

  <transmission name="robotiq_85_left_finger_trans">
    <type>transmission_interface/SimpleTransmission</type>
    <joint name="robotiq_85_left_finger_joint"/>
    <actuator name="robotiq_85_left_finger_motor">
      <hardwareInterface>EffortJointInterface</hardwareInterface>
      <mechanicalReduction>1</mechanicalReduction>
    </actuator>
  </transmission>

  <transmission name="robotiq_85_right_finger_trans">
    <type>transmission_interface/SimpleTransmission</type>
    <joint name="robotiq_85_right_finger_joint"/>
    <actuator name="robotiq_85_right_finger_motor">
      <hardwareInterface>EffortJointInterface</hardwareInterface>
      <mechanicalReduction>1</mechanicalReduction>
    </actuator>
  </transmission>

  <transmission name="robotiq_85_left_inner_knuckle_trans">
    <type>transmission_interface/SimpleTransmission</type>
    <joint name="robotiq_85_left_inner_knuckle_joint"/>
    <actuator name="robotiq_85_left_inner_knuckle_motor">
      <hardwareInterface>EffortJointInterface</hardwareInterface>
      <mechanicalReduction>1</mechanicalReduction>
    </actuator>
  </transmission>

  <transmission name="robotiq_85_right_inner_knuckle_trans">
    <type>transmission_interface/SimpleTransmission</type>
    <joint name="robotiq_85_right_inner_knuckle_joint"/>
    <actuator name="robotiq_85_right_inner_knuckle_motor">
      <hardwareInterface>EffortJointInterface</hardwareInterface>
      <mechanicalReduction>1</mechanicalReduction>
    </actuator>
  </transmission>

  <transmission name="robotiq_85_left_finger_tip_trans">
    <type>transmission_interface/SimpleTransmission</type>
    <joint name="robotiq_85_left_finger_tip_joint"/>
    <actuator name="robotiq_85_left_finger_tip_motor">
      <hardwareInterface>EffortJointInterface</hardwareInterface>
      <mechanicalReduction>1</mechanicalReduction>
    </actuator>
  </transmission>

  <transmission name="robotiq_85_right_finger_tip_trans">
    <type>transmission_interface/SimpleTransmission</type>
    <joint name="robotiq_85_right_finger_tip_joint"/>
    <actuator name="robotiq_85_right_finger_tip_motor">
      <hardwareInterface>EffortJointInterface</hardwareInterface>
      <mechanicalReduction>1</mechanicalReduction>
    </actuator>
  </transmission> -->

  <gazebo reference="universal_robot">
    <material>Gazebo/Blue</material>
  </gazebo>
  <gazebo>
    <plugin name="gazebo_ros_control" filename="libgazebo_ros_control.so">
      <robotNamespace>/ur5_robotiq_joint_limited</robotNamespace>
    </plugin>
  </gazebo>

  <gazebo reference="base_link">
      <selfCollide>true</selfCollide>
      <gravity>true</gravity>
      <turnGravityOff>false</turnGravityOff>
  </gazebo>
  <gazebo reference="upper_arm_link">
      <selfCollide>true</selfCollide>
      <gravity>true</gravity>
      <turnGravityOff>false</turnGravityOff>
  </gazebo>
  <gazebo reference="forearm_link">
      <selfCollide>true</selfCollide>
      <gravity>true</gravity>
      <turnGravityOff>false</turnGravityOff>
  </gazebo>
  <gazebo reference="wrist_1_link">
      <selfCollide>true</selfCollide>
      <gravity>true</gravity>
      <turnGravityOff>false</turnGravityOff>
  </gazebo>
  <gazebo reference="wrist_2_link">
      <selfCollide>true</selfCollide>
      <gravity>true</gravity>
      <turnGravityOff>false</turnGravityOff>
  </gazebo>
  <gazebo reference="wrist_3_link">
      <selfCollide>true</selfCollide>
      <gravity>true</gravity>
      <turnGravityOff>false</turnGravityOff>
  </gazebo>
  <gazebo reference="robotiq_85_adapter_link">
      <selfCollide>true</selfCollide>
      <gravity>true</gravity>
      <turnGravityOff>false</turnGravityOff>
  </gazebo>
  <gazebo reference="robotiq_85_base_link">
      <selfCollide>true</selfCollide>
      <gravity>true</gravity>
      <turnGravityOff>false</turnGravityOff>
  </gazebo>
  <gazebo reference="robotiq_85_left_knuckle_link">
      <selfCollide>true</selfCollide>
      <gravity>true</gravity>
      <turnGravityOff>false</turnGravityOff>
  </gazebo>
  <gazebo reference="robotiq_85_right_knuckle_link">
      <selfCollide>true</selfCollide>
      <gravity>true</gravity>
      <turnGravityOff>false</turnGravityOff>
  </gazebo>
  <gazebo reference="robotiq_85_left_finger_link">
      <selfCollide>true</selfCollide>
      <gravity>true</gravity>
      <turnGravityOff>false</turnGravityOff>
  </gazebo>
  <gazebo reference="robotiq_85_right_finger_link">
      <selfCollide>true</selfCollide>
      <gravity>true</gravity>
      <turnGravityOff>false</turnGravityOff>
  </gazebo>
  <gazebo reference="robotiq_85_left_inner_knuckle_link">
      <selfCollide>true</selfCollide>
      <gravity>true</gravity>
      <turnGravityOff>false</turnGravityOff>
  </gazebo>
  <gazebo reference="robotiq_85_right_inner_knuckle_link">
      <selfCollide>true</selfCollide>
      <gravity>true</gravity>
      <turnGravityOff>false</turnGravityOff>
  </gazebo>
    <gazebo reference="robotiq_85_left_finger_tip_link">
      <selfCollide>true</selfCollide>
      <gravity>true</gravity>
      <turnGravityOff>false</turnGravityOff>
  </gazebo>
  <gazebo reference="robotiq_85_right_finger_tip_link">
      <selfCollide>true</selfCollide>
      <gravity>true</gravity>
      <turnGravityOff>false</turnGravityOff>
  </gazebo>
</robot>
